Workbook

Sheet рабочая 2023 г
A1: FieldName | B1: flNumOnSchema | D1: flSubjectName | E1: flSubjectXin | F1: flSubjectType | G1: flSubjectCountry | H1: flSubjectSex | I1: flSujectSelPrizn | J1: flLandUseType | K1: flLandCadNumber | L1: flLandCategoryL0 | M1: flLandCategoryL1 | N1: flLandUseMode | P1: flLandNasPrizn | Q1: flLandOoptPrizn | R1: flLandUserObl | S1: flLandUserRegion | T1: flLandUserSelO | U1: flLandObl | V1: flLandRegion | W1: flLandSelO | X1: flLandAdr | Y1: flLandUserCount | AF1: flLandTotalArea | AG1: flLandPashni | AH1: flLandMnTotal | AI1: flLandMnSad | AJ1: flLandMnVin | AK1: flLandZal | AL1: flLandSenTotal | AM1: flLandSenUl | AN1: flLandSenPoj | AO1: flLandPasTotal | AP1: flLandPasUl | AQ1: flLandPasObv | AR1: flLandPasZhiv | AS1: flLandSHTotal | AT1: flLandMel | AU1: flLandLesTotal | AV1: flLandLesLes | AW1: flLandLesNotLes | AX1: flLandLesPit | AY1: flLandDknTotal | AZ1: flLandDknZash | BA1: flLandBol | BB1: flLandVodTotal | BC1: flLandVodRek | BD1: flLandVodOz | BE1: flLandVodOzPres | BF1: flLandVodIsk | BG1: flLandKan | BH1: flLandPlosh | BI1: flLandPark | BJ1: flLandPostr | BK1: flLandNar | BL1: flLandProTotal | BM1: flLandProPesk | BN1: flLandProOvr | BO1: flLandProLed | BP1: flLandProDr | BQ1: flLandProTotalAll | BR1: flLandRTotal | BS1: flLandRDrenTotal | BT1: flLandRPashTotal | BU1: flLandRPashDren | BV1: flLandRMnTotal | BW1: flLandRMnDren | BX1: flLandRMnSad | BY1: flLandRMnVin | BZ1: flLandRZalTotal | CA1: flLandRZalDren | CB1: flLandRSenTotal | CC1: flLandRSenDren | CD1: flLandRSenUl | CE1: flLandRPasTotal | CF1: flLandRPasDren | CG1: flLandRPasUl | CH1: flLandRSHTotal | CI1: flLandRSHDren | CJ1: flLandRPro | CK1: flLandPPosOsPrevTotal | CL1: flLandPPosOsPrevMt | CM1: flLandPPosVesCurTotal | CN1: flLandPPosVesCurMt | CO1: flLandPMtPrev | CP1: flLandPPosPrev | CQ1: flLandPPar | CR1: flLandPPosOsCurTotal | CS1: flLandPPosOsCurMtTotal | CT1: flLandPPosOsCurMtPar | CU1: flLandPPosOsCurMtSter | CV1: flLandPPosOsCurMtZal | CW1: flLandPZabTotal | CX1: flLandPZabSter | CY1: flLandPZabMt | CZ1: flLandPZabZel | DA1: flLandPZabZal | DB1: flLandPPashTotal | DC1: flLandPPashMt | DD1: flLandPZalOdn | DE1: flLandPZalSv1 | DF1: flLandPZalTotal | DG1: flLandPPahTotal | DH1: flLandPPahMt
A2: FieldType | B2: nvarchar(2) | D2: nvarchar(2000) | E2: char(12) | F2: char(8) | G2: char(8) | H2: char(8) | I2: char(8) | J2: char(8) | K2: nchar(25) | L2: char(8) | M2: char(8) | N2: char(8) | P2: char(8) | Q2: char(8) | R2: char(12) | S2: char(12) | T2: char(12) | U2: char(12) | V2: char(12) | W2: char(12) | X2: nvarchar(1000) | Y2: int | AF2: decimal(18,5) | AG2: decimal(18,5) | AH2: decimal(18,5) | AI2: decimal(18,5) | AJ2: decimal(18,5) | AK2: decimal(18,5) | AL2: decimal(18,5) | AM2: decimal(18,5) | AN2: decimal(18,5) | AO2: decimal(18,5) | AP2: decimal(18,5) | AQ2: decimal(18,5) | AR2: decimal(18,5) | AS2: decimal(18,5) | AT2: decimal(18,5) | AU2: decimal(18,5) | AV2: decimal(18,5) | AW2: decimal(18,5) | AX2: decimal(18,5) | AY2: decimal(18,5) | AZ2: decimal(18,5) | BA2: decimal(18,5) | BB2: decimal(18,5) | BC2: decimal(18,5) | BD2: decimal(18,5) | BE2: decimal(18,5) | BF2: decimal(18,5) | BG2: decimal(18,5) | BH2: decimal(18,5) | BI2: decimal(18,5) | BJ2: decimal(18,5) | BK2: decimal(18,5) | BL2: decimal(18,5) | BM2: decimal(18,5) | BN2: decimal(18,5) | BO2: decimal(18,5) | BP2: decimal(18,5) | BQ2: decimal(18,5) | BR2: decimal(18,5) | BS2: decimal(18,5) | BT2: decimal(18,5) | BU2: decimal(18,5) | BV2: decimal(18,5) | BW2: decimal(18,5) | BX2: decimal(18,5) | BY2: decimal(18,5) | BZ2: decimal(18,5) | CA2: decimal(18,5) | CB2: decimal(18,5) | CC2: decimal(18,5) | CD2: decimal(18,5) | CE2: decimal(18,5) | CF2: decimal(18,5) | CG2: decimal(18,5) | CH2: decimal(18,5) | CI2: decimal(18,5) | CJ2: decimal(18,5) | CK2: decimal(18,5) | CL2: decimal(18,5) | CM2: decimal(18,5) | CN2: decimal(18,5) | CO2: decimal(18,5) | CP2: decimal(18,5) | CQ2: decimal(18,5) | CR2: decimal(18,5) | CS2: decimal(18,5) | CT2: decimal(18,5) | CU2: decimal(18,5) | CV2: decimal(18,5) | CW2: decimal(18,5) | CX2: decimal(18,5) | CY2: decimal(18,5) | CZ2: decimal(18,5) | DA2: decimal(18,5) | DB2: decimal(18,5) | DC2: decimal(18,5) | DD2: decimal(18,5) | DE2: decimal(18,5) | DF2: decimal(18,5) | DG2: decimal(18,5) | DH2: decimal(18,5)
A3: FieldReference | F3: RefZbSubjectType | G3: RefZbSubjectCountry | H3: RefZbSubjectSex | I3: RefZbSubjectSelPrizn | J3: RefZbLandUseType | L3: RefZbLandCategory | M3: RefZbLandCategory | N3: RefZbLandUseMode | P3: RefZbLandNasPrizn | Q3: RefZbLandOoptPrizn | R3: RefZbLandUserAddress | S3: RefZbLandUserAddress | T3: RefZbLandUserAddress | U3: RefZbLandAddress | V3: RefZbLandAddress | W3: RefZbLandAddress
A4: FieldReferenceLevel | L4: 0 | M4: 1 | R4: 0 | S4: 1 | T4: 2 | U4: 0 | V4: 1 | W4: 2
A5: FieldRegex | E5: ^\d{12}$ | K5: ^\d{2}\-\d{3}\-\d{3}(\-\d{3,4})*$
A6: FieldRequired | D6: 1 | F6: 1 | G6: 1 | H6: 1 | I6: 1 | J6: 1 | L6: 1 | M6: 1 | N6: 1 | P6: 1 | Q6: 1 | R6: 1 | S6: 1 | T6: 1 | U6: 1 | V6: 1 | W6: 1 | Y6: 1
A7: FieldLogicErrMsg | Y7: Количество землепользователей должно быть не менее одного | AL7: "Всего" не может быть меньше "в т.ч." | AO7: "Всего" не может быть меньше "в т.ч." | BD7: "Всего" не может быть меньше "в т.ч." | BT7: "Всего" не может быть меньше "в т.ч." | BV7: "Всего" не может быть меньше "в т.ч." | BZ7: "Всего" не может быть меньше "в т.ч." | CB7: "Всего" не может быть меньше "в т.ч." | CE7: "Всего" не может быть меньше "в т.ч." | CK7: "Всего" не может быть меньше "в т.ч." | CM7: "Всего" не может быть меньше "в т.ч." | CR7: "Всего" не может быть меньше "в т.ч." | DB7: "Всего" не может быть меньше "в т.ч." | DG7: "Всего" не может быть меньше "в т.ч."
A8: FieldLogic | Y8: =#REF!>=1 -> #REF! | AL8: =#REF!>=#REF!+#REF! -> #REF! | AO8: =#REF!>=#REF!+#REF!+#REF! -> #REF! | BD8: =#REF!>=#REF! -> #REF! | BT8: =#REF!>=#REF! -> #REF! | BV8: =AND(#REF!>=#REF!,#REF!>=#REF!+#REF!) -> #REF! | BZ8: =#REF!>=#REF! -> #REF! | CB8: =AND(#REF!>=#REF!,#REF!>=#REF!) -> #REF! | CE8: =AND(#REF!>=#REF!,#REF!>=#REF!) -> #REF! | CK8: =#REF!>=#REF! -> #REF! | CM8: =#REF!>=#REF! -> #REF! | CR8: =#REF!>=#REF! -> #REF! | DB8: =#REF!>=#REF! -> #REF! | DG8: =#REF!>=#REF! -> #REF!
A9: FieldFixedCol | D9: 1
A10: FieldTextStart | D10: Жер туралы ақпараттар Сведения об участке | AF10: Жердің сандық көрсеткіштері Численные показатели участка | BR10: Суармалы жерлер Регулярное орошение земель | CK10: Егістік және тыңайған, нақтысы Пашни и залежи, детализация | DI10: Шабындықтар мен жайылымдарды түбегейлі жақсарту жерлерін пайдалану Использование земель коренного улучшения сенокосов и пастбищ
B11: № | C11: Санаттардың атаулары Наименование категории | D11: Жер учаскелерінің меншік иелері мен жер пайдаланушылардың атауы (Аты-жөні ұйымның атауы) Наименование собственников земельных участков и землепользователей (ФИО Наименование организации) | E11: Жер пайдаланушының, иеленушінің ЖСН,БСН ИИН,БИН собственника, землепользователя | F11: Субъект түрі Вид субъекта | G11: Шетелдік иеленуші жер пайдаланушы (шетелдік субъектілерді есепке алу үшін) Страна собственника землепользователя (для учета иностранных субъектов) | H11: Жер пайдаланушының иеленушінің жынысы Пол собственника, землепользователя | I11: Меншік иесінің, жер пайдаланушының белгісі (Ауылдық, Қалалық) Признак собственника, землепользователя (Сельский, Городской) | J11: Пайдалану түрі Вид пользования | K11: Кадастрлық нөмері Кадастровый номер | L11: Жер санаты Категория земель | P11: Елді мекен белгісі Признак населенного пункта | Q11: Ерекше қорғалатын табиғи аумақ белгісі Признак особо охраняемой территории | R11: Жер пайдаланушының орналасқан орны(жалға алу, облыстар) Месторасположение землепользователя (аренды областей) | U11: Жер учаскесінің орналасқан жері Месторасположение земельного участка | Y11: Жер пайдаланушылардың саны Количество землепользователей | Z11: Аренда мерзімі Срок аренды | AB11: ЖУ негізі құқығының туындауы Основание возникновение права на ЗУ | AF11: Жалпы алаңы Общая площадь (га) (41+65) | AG11: Егістіктер Пашни | AH11: Көп жылдық екпелер Многолетних насаждений | AK11: Тыңайған Залежи | AL11: Шабындықтар Сенокосов | AO11: Жайылымдар Пастбищ | AS11: Барлық ауылшаруашылығы алқаптар Всего с/х угодий (29+30+33+34+37) | AT11: Мелиоративтік құрылыс сатысындағы жерлер Земли, находящиеся в стадии мелиоративного строительства | AU11: Орман алаңдары Лесных площадей | AY11: Орман қорына кірмейтін ағаш-бұталы екпелер Древесно-кустарниковые насаждения, не входящие в лесной фонд | BA11: Батпақтар Болота | BB11: Су асты Под водой | BG11: Арналар және коллекторлардың асты ндағы Под каналами, коллекторами | BH11: Алаңдар, жолдар, көшелер астындағы жерлер Под площадями, дорогами, улицами | BI11: Парктер, скверлер және бульварлардың астындағы Под парками, скверами и бульварами | BJ11: Құрылыстар астындағы Под постройками | BK11: Бұзылған жерлер Нарушенных земель | BL11: Басқа жерле Прочих угодий | BQ11: Бөгде жерлердің барлығы Прочие, всего (42+43+47+49+50+55+56+57+58+59+60) | BR11: Суармалы жердің жалпы көлемі Общая площадь орошаемых земель | BT11: Егістік Пашни | BV11: Көп жылдық екпелер Многолетних насаждений | BZ11: Тыңайған Залежи | CB11: Шабындық Сенокосов | CE11: Жайылым Пастбищ | CH11: Барлық ауылшаруашылығы алқаптар Итого с/х угодий | CJ11: Бөгде жерлердің барлығы Прочие в орошаемых землях (не орошаемые) | CK11: Өткен жылдың күзінде егілген күздік дақылдары Посеяно озимых культур осенью прошлого года | CM11: Есепті жылдың жаздық дақылдары көктемде егілгені Посеяно весной отчетного года яровых культур | CO11: Өткен жылғы көп жылдық екпелердің ауданы Площади под многолетними травами прошлых лет | CP11: Барлық егу жұмыспен қамтылғаны Всего было занято посевами | CQ11: Тыңайтуға жыртылғаны Вспахано паров | CR11: Күздегі есепті жылдың күзгі егістері, Посеяно озимых осенью отчетного года | CW11: Өңдеу үшін жырту Вспахано под зябь | DB11: Егістік Пашни | DD11: Тыңайғаны Залежи | DG11: Жыртылған жерлер Пахатнопригодные земли | DI11: Өткен жылғы күзгі себу Посев осени прошлого года | DL11: Есепті жылғы көктемгі себу Посев весны отчетного года | DO11: Өткен жылғы егілген көпжылдық шөптер Многолетних трав посева прошлого года | DP11: Барлығы егінмен қамтылғаны Всего было занято посевами (гр.1+2+4+5+7) | DQ11: Тыңайтуға жыртылғаны Вспахано паров | DT11: Есепті жылдың күзін себу Посев осени отчетного года | DV11: Егу жүргізілді Посев произведен | DZ11: Өңдеу үшін жырту Вспахано зяби | EE11: Өңдеудегі барлық жерлер Всего земель в обработке (гр.8+9+17+21+22) | EF11: Тыңайғанның қалдығы Остаток залежи | EG11: Жердің түбегейлі жақсартылғаны Земли корен. улучшения
L12: жер санаты категория земли | M12: жердің ішкі санаты подкатегория земли | N12: пайдалану түрі режим использования | O12: вид использования | R12: облыс область | S12: аймақ (аудан) регион (район) | T12: ауылдық округ сельский округ | U12: облыс область | V12: аймақ (аудан) регион (район) | W12: ауылдық округ сельский округ | X12: елді-мекен, үй,пәтер населенный пункт, дом, кв | Z12: пайда болу күні дата возникновение (күні.айы.жылы) | AA12: аяқталу мерзімі дата оканчание (күні.айы.жылы) | AB12: құқықты белгілейтін құжаттың аталуы наименование право устанавливающего документа | AC12: нөмері номер | AD12: күні дата (күні.айы.жылы) | AE12: құжаттың көшірмесі копия документа | AH12: Барлығы Всего | AI12: соның ішінде: из них: | AL12: Барлығы Всего | AM12: соның ішінде: из них: | AO12: Барлығы Всего | AP12: оның ішінде: из них | AU12: Барлығы Всего (44+45+46) | AV12: соның ішінде: в том числе | AY12: Барлығы Всего | AZ12: қорғайтын защитных | BB12: Барлығы Всего (51+52+53+54) | BC12: соның ішінде: из них: | BL12: Барлығы Всего (61+62+63+64) | BM12: соның ішінде: из них: | BR12: Барлығы Всего (44+46) | BS12: соның ішінде дренажбен қамтылғандары из них обеспеченых дренажом | BT12: Барлығы Всего | BU12: соның ішінде дренажбен қамтылғандары из них обеспеченых дренажом | BV12: Барлығы Всего | BW12: соның ішінде дренажбен қамтылғандары из них обеспеченых дренажом | BX12: баулар садов | BY12: жүзімдіктер виноградников | BZ12: Барлығы Всего | CA12: соның ішінде дренажбен қамтылғандары из них обеспеченых дренажом | CB12: Барлығы Всего | CC12: соның ішінде: из них: | CE12: Барлығы Всего | CF12: соның ішінде: из них: | CH12: Барлығы Всего (30+32+36+38+41) | CI12: соның ішінде дренажбен қамтылғандары из них обеспе- ченых дренажом (31+33+37+39+42) | CK12: Барлығы егілгені Всего посеяно | CL12: о.і. көп жылдық екпелері в т.ч. многолетних трав | CM12: Барлығы егілгені Всего посеяно | CN12: о.і. көп жылдық екпелердің есепті жылдың көктемдегісі в.т.ч. многолетних трав весны отчетного года | CR12: Барлық егілгені Всего посеяно | CS12: о.і. көп жылдық шөп в т.ч. многолетних трав | CW12: Барлығы Всего | CX12: соның ішінде: в том числе | DB12: Егістіктің барлығы Пашни всего | DC12: о.і. көп жылдық екпелері в т.ч. многолетних трав (гр.2+4+5+9+15) | DD12: соның ішінде: в том числе | DF12: Барлық тыңайғаны Залежи всего | DG12: Барлық егістік+тыңайған жерлер Всего пашня+залежи | DH12: о.і. көп жылдық шөп вт.ч. многолетних трав = гр. 19 | DI12: күздік дақылдар озимых культур | DJ12: таза түрдегі көпжылдық шөптер многолетних трав в чистом виде | DK12: жабынды көпжылдық шөптер многолетних трав под покров | DL12: жаздық дақылдар яровых культур | DM12: таза түрдегі көпжылдық шөптер многолетних трав в чистом виде | DN12: жабынды көпжылдық шөптер многолетних трав под покров | DQ12: Барлығы Всего | DR12: соның ішінде: в том числе | DT12: күздік дақылдар озимых культур | DU12: таза түрдегі көпжылдық шөптер многолетних трав в чистом виде | DV12: жабынды көпжылдық шөптер многолетних трав под покров | DW12: тыңайту по парам | DX12: ағымдағы жылдың қалдығы бойынша по стерне текущего года | DY12: өткен жылғы тыңайған жерлер мен қалдығы бойынша по залежи и стерне прошлого года | DZ12: Барлығы Всего | EA12: соның ішінде: в том числе: | EG12: Барлығы Всего (гр.23+24) | EH12: о.і. жақсартылғаны в т.ч. улучшенных (гр.2+3+5+6+7+13+14+20)=КУ
AI13: бақтар садов | AJ13: жүзімдіктер виноградников | AM13: жақсартылған улучшенных | AN13: жайылма пойменные | AP13: жақсартылған, түбегейлі жақсартылғанды қоса алғанда из них улучшенные, включая коренное улучшение | AQ13: суландырылған обводненные | AR13: шалғайдағы мал шаруашылығы үшін для отгонного животноводства | AV13: орман көмкерген покрытых лесом | AW13: орман көмкермеген не покрытых лесом | AX13: питомниктер және бірікпеген ағаштар питомников и несомкнувшихся культур | BC13: өзендер мен жылғалар астындағы под реками и ручьями | BD13: көл астындағы под озерами | BE13: соның ішінде тұщы сулы в т.ч. пресноводных | BF13: жасанды су айдындары искуственныме водоемы | BM13: құмдар песков | BN13: жыралар мен сайлар оврагов | BO13: мұз басқан жерлер ледников | BP13: басқа алқаптар других угодий | CC13: дренажбен қамтылғандары обеспе- ченых дрена- жом | CD13: жақсартылған, түбегейлі жақсартылғаны улучшенных, КУ | CF13: дренажбен қамтылғандары обеспеченых дренажом | CG13: жақсартылған, түбегейлі жақсартылғаны улучшенных, КУ | CS13: Барлығы көп жылдық шөптер Всего многолетних трав | CT13: соның ішінде: в том числе: | CX13: ағымдағы жылдың қалдығы стерни текуще года | CY13: көп жылдық шөп многолетних трав | CZ13: тыңның барлық түрлері целина всех видов | DA13: өткен жылғы қалдық шоғырына залежи и стерни прошлого года | DD13: бір жылдық (өткен жылдың таратылмаған қалдық) однолетних (нераспаханной стерни прошлого года) | DE13: 1 жылдан аса свыше1 года | DR13: тың (жаңа жерлер) целины (новых земель) | DS13: өткен жылғы қалдық шоғырына залежи и стерни прошлого года | EA13: өткен жылдың қалдығы стерни прошлого года | EB13: көпжылдық шөптер(бұрын егілген жерлер) многолетних трав(ранее залуженных земель) | EC13: өткен жылғы тыңайған жерлер мен қалдығы бойынша залежи и стерни прошлого года | ED13: тың (жаңа жерлер) целины (новых земель)
A14: FieldTextEnd | CT14: тыңайтуға под парами | CU14: ағымдағы жылдың қалдығы под стерней текущего года | CV14: өткен жылғы қалдық шоғырына под залежи стерни от прошлого года
A15: FieldCodeName | B15: А1 | C15: А2 | D15: 1 | E15: 2 | F15: 3 | G15: 4 | H15: 5 | I15: 6 | J15: 7 | K15: 8 | L15: 9 | M15: 10 | N15: 11 | O15: 11 | P15: 12 | Q15: 13 | R15: 14 | S15: 15 | T15: 16 | U15: 17 | V15: 18 | W15: 19 | X15: 20 | Y15: 21 | Z15: 22 | AA15: 23 | AB15: 24 | AC15: 25 | AD15: 26 | AE15: 27 | AF15: 28 | AG15: 29 | AH15: 30 | AI15: 31 | AJ15: 32 | AK15: 33 | AL15: 34 | AM15: 35 | AN15: 36 | AO15: 37 | AP15: 38 | AQ15: 39 | AR15: 40 | AS15: 41 | AT15: 42 | AU15: 43 | AV15: 44 | AW15: 45 | AX15: 46 | AY15: 47 | AZ15: 48 | BA15: 49 | BB15: 50 | BC15: 51 | BD15: 52 | BE15: 53 | BF15: 54 | BG15: 55 | BH15: 56 | BI15: 57 | BJ15: 58 | BK15: 59 | BL15: 60 | BM15: 61 | BN15: 62 | BO15: 63 | BP15: 64 | BQ15: 65 | BR15: 28 | BS15: 29 | BT15: 30 | BU15: 31 | BV15: 32 | BW15: 33 | BX15: 34 | BY15: 35 | BZ15: 36 | CA15: 37 | CB15: 38 | CC15: 39 | CD15: 40 | CE15: 41 | CF15: 42 | CG15: 43 | CH15: 44 | CI15: 45 | CJ15: 46 | CK15: 1 | CL15: 2 | CM15: 3 | CN15: 4 | CO15: 5 | CP15: 6 | CQ15: 7 | CR15: 8 | CS15: 9 | CT15: 10 | CU15: 11 | CV15: 12 | CW15: 13 | CX15: 14 | CY15: 15 | CZ15: 16 | DA15: 17 | DB15: 18 | DC15: 19 | DD15: 20 | DE15: 21 | DF15: 22 | DG15: 23 | DH15: 24 | DI15: 1 | DJ15: 2 | DK15: 3 | DL15: 4 | DM15: 5 | DN15: 6 | DO15: 7 | DP15: 8 | DQ15: 9 | DR15: 10 | DS15: 11 | DT15: 12 | DU15: 13 | DV15: 14 | DW15: 15 | DX15: 16 | DY15: 17 | DZ15: 18 | EA15: 19 | EB15: 20 | EC15: 21 | ED15: 22 | EE15: 23 | EF15: 24 | EG15: 25 | EH15: 26
B16: контрол | C16: Земли сельскохозяйственного назначения (строка 1.1+1.2) | Y16: =SUM(Y19:Y32) -> 4090 | AF16: =SUM(AS16:AU16,AY16,BA16:BB16,BG16:BL16) -> 7232.5 | AG16: 4987.5 | AH16: 0.8 | AI16: 0.4 | AK16: 40.8 | AL16: 17.6 | AM16: 6.7 | AO16: 1954 | AP16: 379.5 | AQ16: 702.4 | AR16: =SUM(AR19:AR32) -> 0 | AS16: =SUM(AG16,AH16,AK16,AL16,AO16) -> 7000.7 | AU16: 0.2 | AX16: 0.2 | AY16: 48.3 | AZ16: 6.4 | BA16: 42.8 | BB16: =SUM(BC16,BD16,BF16) -> 63.3 | BC16: 4.5 | BD16: 56.6 | BE16: 32.2 | BF16: 2.2 | BG16: 0.1 | BH16: 31.8 | BJ16: 0.8 | BK16: 0.4 | BL16: =SUM(BM16:BP16) -> 44.1 | BN16: 0.1 | BP16: 44 | BQ16: =SUM(AF16-AS16) -> 231.8
Y17: =SUM(Y33+Y205) -> 4090 | AF17: =SUM(AS17:AU17,AY17,BA17:BB17,BG17:BL17) -> 7232.5 | AG17: =SUM(AG33+AG205) -> 4987.5 | AH17: =SUM(AH33+AH205) -> 0.8 | AI17: =SUM(AI33+AI205) -> 0.4 | AJ17: =SUM(AJ33+AJ205) -> 0 | AK17: =SUM(AK33+AK205) -> 40.8 | AL17: =SUM(AL33+AL205) -> 17.6 | AM17: =SUM(AM33+AM205) -> 6.7 | AN17: =SUM(AN33+AN205) -> 0 | ... AR17: =SUM(AR33+AR205) -> 0 | AS17: =SUM(AG17,AH17,AK17,AL17,AO17) -> 7000.7 | AT17: =SUM(AT33+AT205) -> 0 | AU17: =SUM(AU33+AU205) -> 0.2 | AV17: =SUM(AV33+AV205) -> 0 | AW17: =SUM(AW33+AW205) -> 0 | AX17: =SUM(AX33+AX205) -> 0.2 | AY17: =SUM(AY33+AY205) -> 48.3 | AZ17: =SUM(AZ33+AZ205) -> 6.4 | BA17: =SUM(BA33+BA205) -> 42.8 | BB17: =SUM(BC17,BD17,BF17) -> 63.3 | BC17: =SUM(BC33+BC205) -> 4.5 | BD17: =SUM(BD33+BD205) -> 56.6 | BE17: =SUM(BE33+BE205) -> 32.2 | BF17: =SUM(BF33+BF205) -> 2.2 | BG17: =SUM(BG33+BG205) -> 0.1 | BH17: =SUM(BH33+BH205) -> 31.8 | BI17: =SUM(BI33+BI205) -> 0 | BJ17: =SUM(BJ33+BJ205) -> 0.8 | BK17: =SUM(BK33+BK205) -> 0.4 | BL17: =SUM(BM17:BP17) -> 44.1 | BM17: =SUM(BM33+BM205) -> 0 | BN17: =SUM(BN33+BN205) -> 0.1 | BO17: =SUM(BO33+BO205) -> 0 | BP17: =SUM(BP33+BP205) -> 44 | BQ17: =SUM(AF17-AS17) -> 231.8 | BR17: =SUM(BR33+BR205) -> 20.6 | BS17: =SUM(BS33+BS205) -> 0 | BT17: =SUM(BT33+BT205) -> 17.3 | BU17: =SUM(BU33+BU205) -> 0 | BV17: =SUM(BV33+BV205) -> 0 | BW17: =SUM(BW33+BW205) -> 0 | BX17: =SUM(BX33+BX205) -> 0 | BY17: =SUM(BY33+BY205) -> 0 | ... CJ17: =SUM(CJ33+CJ205) -> 0 | CK17: =SUM(CK33,CK205) -> 1.2 | CL17: =SUM(CL33,CL205) -> 0 | CM17: =SUM(CM33,CM205) -> 4061.7 | CN17: =SUM(CN33,CN205) -> 8 | CO17: =SUM(CO33,CO205) -> 224.5 | CP17: =SUM(CM17,CK17,CO17) -> 4287.4 | CQ17: =SUM(CQ33,CQ205) -> 575.7 | CR17: =SUM(CR33,CR205) -> 0.3 | CS17: =SUM(CS33,CS205) -> 0 | CT17: =SUM(CT33,CT205) -> 0 | CU17: =SUM(CU33,CU205) -> 0 | CV17: =SUM(CV33,CV205) -> 0 | CW17: =SUM(CW33,CW205) -> 720.2 | CX17: =SUM(CX33,CX205) -> 618.1 | ... DA17: =SUM(DA33,DA205) -> 81 | DB17: =SUM(CP17,CQ17,DA17) -> 4944.1 | DC17: =SUM(CO17,CN17) -> 232.5 | DE17: =SUM(DE33,DE205) -> 57.4 | DF17: =SUM(DF33,DF205) -> 57.4 | DG17: =SUM(DB17,DF17) -> 5001.5 | DH17: =SUM(DC17) -> 232.5 | DI17: =SUM(DI34,DI206) -> 0 | DJ17: =SUM(DJ34,DJ206) -> 0
Y18: =SUM(Y19:Y32) -> 4090 | AF18: =SUM(AS18:AU18,AY18,BA18:BB18,BG18:BL18) -> 7232511.8 | AG18: =SUM(AG19:AG32) -> 4987500.7 | AH18: =SUM(AH19:AH32) -> 857 | AI18: =SUM(AI19:AI32) -> 449 | AJ18: =SUM(AJ19:AJ32) -> 45 | AK18: =SUM(AK19:AK32) -> 40780 | AL18: =SUM(AL19:AL32) -> 17522 | AM18: =SUM(AM19:AM32) -> 6660 | AN18: =SUM(AN19:AN32) -> 0 | ... AR18: =SUM(AR19:AR32) -> 0 | AS18: =SUM(AG18,AH18,AK18,AL18,AO18) -> 7000668.4 | AT18: =SUM(AT19:AT32) -> 0 | AU18: =SUM(AU19:AU32) -> 182 | AV18: =SUM(AV19:AV32) -> 7 | AW18: =SUM(AW19:AW32) -> 0 | AX18: =SUM(AX19:AX32) -> 175 | AY18: =SUM(AY19:AY32) -> 48270.4 | AZ18: =SUM(AZ19:AZ32) -> 6401 | BA18: =SUM(BA19:BA32) -> 42777.6 | BB18: =SUM(BC18,BD18,BF18) -> 63340.1 | BC18: =SUM(BC19:BC32) -> 4517 | BD18: =SUM(BD19:BD32) -> 56665.1 | BE18: =SUM(BE19:BE32) -> 32152 | BF18: =SUM(BF19:BF32) -> 2158 | BG18: =SUM(BG19:BG32) -> 129 | BH18: =SUM(BH19:BH32) -> 31840.3 | BI18: =SUM(BI19:BI32) -> 13 | BJ18: =SUM(BJ19:BJ32) -> 784 | BK18: =SUM(BK19:BK32) -> 397 | BL18: =SUM(BM18:BP18) -> 44110 | BM18: =SUM(BM19:BM32) -> 45 | BN18: =SUM(BN19:BN32) -> 51 | BO18: =SUM(BO19:BO32) -> 0 | BP18: =SUM(BP19:BP32) -> 44014 | BQ18: =SUM(AF18-AS18) -> 231843.4 | BR18: =SUM(BR19:BR32) -> 20640 | BS18: =SUM(BS19:BS32) -> 0 | BT18: =SUM(BT19:BT32) -> 17329 | BU18: =SUM(BU19:BU32) -> 0 | BV18: =SUM(BV19:BV32) -> 5 | BW18: =SUM(BW19:BW32) -> 0 | BX18: =SUM(BX19:BX32) -> 0 | BY18: =SUM(BY19:BY32) -> 0 | ... CJ18: =SUM(CJ19:CJ32) -> 2 | CK18: =SUM(CK19:CK31) -> 1211 | CL18: =SUM(CL19:CL31) -> 0 | CM18: =SUM(CM19:CM31) -> 4061708.5 | CN18: =SUM(CN19:CN31) -> 7960 | CO18: =SUM(CO19:CO31) -> 224541 | CP18: =SUM(CM18,CK18,CO18) -> 4287460.5 | CQ18: =SUM(CQ19:CQ31) -> 575612.49 | CR18: =SUM(CR19:CR31) -> 333 | CS18: =SUM(CS19:CS31) -> 0 | CT18: =SUM(CT19:CT31) -> 0 | CU18: =SUM(CU19:CU31) -> 0 | CV18: =SUM(CV19:CV31) -> 0 | CW18: =SUM(CW19:CW31) -> 720217 | CX18: =SUM(CX19:CX31) -> 618164 | ... DA18: =SUM(DA19:DA31) -> 81046 | DB18: =SUM(CP18,CQ18,DA18) -> 4944119 | DC18: =SUM(CO18,CN18) -> 232501 | DD18: =SUM(DD19:DD31) -> 0 | DE18: =SUM(DE19:DE31) -> 51 | DF18: =SUM(DF19:DF31) -> 51 | DG18: =SUM(DB18,DF18) -> 4944170 | DH18: =SUM(DC18) -> 232501
C19: Айыртауский | Y19: =SUM(Y35,Y207) -> 372 | AF19: =SUM(AS19:AU19,AY19,BA19:BB19,BG19:BL19) -> 606719 | AG19: =SUM(AG35,AG207) -> 433609 | AH19: =SUM(AH35,AH207) -> 88 | AI19: =SUM(AI35,AI207) -> 55 | AJ19: =SUM(AJ35,AJ207) -> 0 | AK19: =SUM(AK35,AK207) -> 0 | AL19: =SUM(AL35,AL207) -> 385 | AM19: =SUM(AM35,AM207) -> 0 | AN19: =SUM(AN35,AN207) -> 0 | ... AR19: =SUM(AR35,AR207) -> 0 | AS19: =SUM(AG19,AH19,AK19,AL19,AO19) -> 594389 | AT19: =SUM(AT35,AT207) -> 0 | AU19: =SUM(AV19:AX19) -> 0 | AV19: =SUM(AV35,AV207) -> 0 | AW19: =SUM(AW35,AW207) -> 0 | AX19: =SUM(AX35,AX207) -> 0 | AY19: =SUM(AY35,AY207) -> 2625 | AZ19: =SUM(AZ35,AZ207) -> 1156 | BA19: =SUM(BA35,BA207) -> 2881 | BB19: =SUM(BC19,BD19,BF19) -> 3152 | BC19: =SUM(BC35,BC207) -> 328 | BD19: =SUM(BD35,BD207) -> 2573 | BE19: =SUM(BE35,BE207) -> 428 | BF19: =SUM(BF35,BF207) -> 251 | BG19: =SUM(BG35,BG207) -> 0 | BH19: =SUM(BH35,BH207) -> 2722 | BI19: =SUM(BI35,BI207) -> 9 | BJ19: =SUM(BJ35,BJ207) -> 189 | BK19: =SUM(BK35,BK207) -> 132 | BL19: =SUM(BM19:BP19) -> 620 | BM19: =SUM(BM35,BM207) -> 35 | BN19: =SUM(BN35,BN207) -> 51 | BO19: =SUM(BO35,BO207) -> 0 | BP19: =SUM(BP35,BP207) -> 534 | BQ19: =SUM(AF19-AS19) -> 12330 | BR19: =SUM(BR35,BR207) -> 470 | BS19: =SUM(BS35,BS207) -> 0 | BT19: =SUM(BT35,BT207) -> 470 | BU19: =SUM(BU35,BU207) -> 0 | BV19: =SUM(BV35,BV207) -> 0 | BW19: =SUM(BW35,BW207) -> 0 | BX19: =SUM(BX35,BX207) -> 0 | BY19: =SUM(BY35,BY207) -> 0 | ... CH19: =SUM(CH35,CH207) -> 470 | CI19: =SUM(CI35,CI51) -> 0 | CJ19: =SUM(CJ35,CJ51) -> 0 | CK19: =SUM(CK35,CK207) -> 0 | CL19: =SUM(CL35,CL207) -> 0 | CM19: =SUM(CM35,CM207) -> 353247 | CN19: =SUM(CN35,CN207) -> 1490 | CO19: =SUM(CO35,CO207) -> 25119 | CP19: =SUM(CM19,CK19,CO19) -> 378366 | CQ19: =SUM(CQ35,CQ207) -> 47467 | CR19: =SUM(CR35,CR51) -> 0 | CS19: =SUM(CS35,CS51) -> 0 | CT19: =SUM(CT35,CT51) -> 0 | CU19: =SUM(CU35,CU51) -> 0 | CV19: =SUM(CV35,CV51) -> 0 | CW19: =SUM(CW35,CW51) -> 0 | CX19: =SUM(CX35,CX51) -> 0 | CY19: =SUM(CY35,CY51) -> 0 | ... DA19: =SUM(DA35,DA51) -> 0 | DB19: =SUM(CP19,CQ19,DA19) -> 425833 | DC19: =SUM(CO19,CN19) -> 26609 | DD19: =SUM(DD35,DD207) -> 0 | DE19: =SUM(DE35,DE51) -> 0 | DF19: =SUM(DF35,DF51) -> 0 | DG19: =SUM(DB19,DF19) -> 425833 | DH19: =SUM(DC19) -> 26609 | DI19: =SUM(DI35,DI51) -> 0 | DJ19: =SUM(DJ35,DJ51) -> 0 | DK19: =SUM(DK35,DK51) -> 0 | DL19: =SUM(DL35,DL51) -> 0 | DM19: =SUM(DM35,DM51) -> 0 | DN19: =SUM(DN35,DN51) -> 0 | DO19: =SUM(DO35,DO51) -> 0 | DP19: =SUM(DP35,DP51) -> 0 | ... EH19: =SUM(EH35,EH51) -> 0
C20: Акжарский | Y20: =SUM(Y36,Y208) -> 287 | AF20: =SUM(AS20:AU20,AY20,BA20:BB20,BG20:BL20) -> 529053 | AG20: =SUM(AG36,AG208) -> 345955 | AH20: =SUM(AH36,AH208) -> 2 | AI20: =SUM(AI36,AI208) -> 2 | AJ20: =SUM(AJ36,AJ208) -> 0 | AK20: =SUM(AK36,AK208) -> 0 | AL20: =SUM(AL36,AL208) -> 1796 | AM20: =SUM(AM36,AM208) -> 1727 | AN20: =SUM(AN36,AN208) -> 0 | ... AR20: =SUM(AR36,AR208) -> 0 | AS20: =SUM(AG20,AH20,AK20,AL20,AO20) -> 522812 | AT20: =SUM(AT36,AT208) -> 0 | AU20: =SUM(AV20:AX20) -> 0 | AV20: =SUM(AV36,AV208) -> 0 | AW20: =SUM(AW36,AW208) -> 0 | AX20: =SUM(AX36,AX208) -> 0 | AY20: =SUM(AY36,AY208) -> 1000 | AZ20: =SUM(AZ36,AZ208) -> 536 | BA20: =SUM(BA36,BA208) -> 843 | BB20: =SUM(BC20,BD20,BF20) -> 1320 | BC20: =SUM(BC36,BC208) -> 271 | BD20: =SUM(BD36,BD208) -> 691 | BE20: =SUM(BE36,BE208) -> 0 | BF20: =SUM(BF36,BF208) -> 358 | BG20: =SUM(BG36,BG208) -> 0 | BH20: =SUM(BH36,BH208) -> 1874 | BI20: =SUM(BI36,BI208) -> 0 | BJ20: =SUM(BJ36,BJ208) -> 113 | BK20: =SUM(BK36,BK208) -> 0 | BL20: =SUM(BM20:BP20) -> 1091 | BM20: =SUM(BM36,BM208) -> 0 | BN20: =SUM(BN36,BN208) -> 0 | BO20: =SUM(BO36,BO208) -> 0 | BP20: =SUM(BP36,BP208) -> 1091 | BQ20: =SUM(AF20-AS20) -> 6241 | BR20: =SUM(BR36,BR208) -> 0 | BS20: =SUM(BS36,BS208) -> 0 | BT20: =SUM(BT36,BT208) -> 0 | BU20: =SUM(BU36,BU208) -> 0 | BV20: =SUM(BV36,BV208) -> 0 | BW20: =SUM(BW36,BW208) -> 0 | BX20: =SUM(BX36,BX208) -> 0 | BY20: =SUM(BY36,BY208) -> 0 | ... CO20: =SUM(CO36,CO208) -> 18748 | CP20: =SUM(CM20,CK20,CO20) -> 277425 | CQ20: =SUM(CQ36,CQ208) -> 72400 | CR20: =SUM(CR36,CR52) -> 0 | CS20: =SUM(CS36,CS52) -> 0 | CT20: =SUM(CT36,CT52) -> 0 | CU20: =SUM(CU36,CU52) -> 0 | CV20: =SUM(CV36,CV52) -> 0 | CW20: =SUM(CW36,CW208) -> 0 | CX20: =SUM(CX36,CX208) -> 0 | CY20: =SUM(CY36,CY208) -> 0 | CZ20: =SUM(CZ36,CZ208) -> 0 | DA20: =SUM(DA36,DA208) -> 0 | DB20: =SUM(CP20,CQ20,DA20) -> 349825 | DC20: =SUM(CO20,CN20) -> 18748 | DD20: =SUM(DD36,DD208) -> 0 | DE20: =SUM(DE36,DE52) -> 0 | DF20: =SUM(DF36,DF52) -> 0 | DG20: =SUM(DB20,DF20) -> 349825 | DH20: =SUM(DC20) -> 18748 | DI20: =SUM(DI36,DI52) -> 0 | DJ20: =SUM(DJ36,DJ52) -> 0 | DK20: =SUM(DK36,DK52) -> 0 | DL20: =SUM(DL36,DL52) -> 0 | DM20: =SUM(DM36,DM52) -> 0 | DN20: =SUM(DN36,DN52) -> 0 | DO20: =SUM(DO36,DO52) -> 0 | DP20: =SUM(DP36,DP52) -> 0 | ... EH20: =SUM(EH36,EH52) -> 0
C21: Аккайынский | Y21: =SUM(Y37,Y209) -> 243 | AF21: =SUM(AS21:AU21,AY21,BA21:BB21,BG21:BL21) -> 356746 | AG21: =SUM(AG37,AG209) -> 241726 | AH21: =SUM(AH37,AH209) -> 151 | AI21: =SUM(AI37,AI209) -> 75 | AJ21: =SUM(AJ37,AJ209) -> 0 | AK21: =SUM(AK37,AK209) -> 0 | AL21: =SUM(AL37,AL209) -> 0 | AM21: =SUM(AM37,AM209) -> 0 | AN21: =SUM(AN37,AN209) -> 0 | ... AR21: =SUM(AR37,AR209) -> 0 | AS21: =SUM(AG21,AH21,AK21,AL21,AO21) -> 340442 | AT21: =SUM(AT37,AT209) -> 0 | AU21: =SUM(AV21:AX21) -> 0 | AV21: =SUM(AV37,AV209) -> 0 | AW21: =SUM(AW37,AW209) -> 0 | AX21: =SUM(AX37,AX209) -> 0 | AY21: =SUM(AY37,AY209) -> 5733 | AZ21: =SUM(AZ37,AZ209) -> 455 | BA21: =SUM(BA37,BA209) -> 3342 | BB21: =SUM(BC21,BD21,BF21) -> 4499 | BC21: =SUM(BC37,BC209) -> 0 | BD21: =SUM(BD37,BD209) -> 4458 | BE21: =SUM(BE37,BE209) -> 717 | BF21: =SUM(BF37,BF209) -> 41 | BG21: =SUM(BG37,BG209) -> 11 | BH21: =SUM(BH37,BH209) -> 1852 | BI21: =SUM(BI37,BI209) -> 1 | BJ21: =SUM(BJ37,BJ209) -> 127 | BK21: =SUM(BK37,BK209) -> 8 | BL21: =SUM(BM21:BP21) -> 731 | BM21: =SUM(BM37,BM209) -> 0 | BN21: =SUM(BN37,BN209) -> 0 | BO21: =SUM(BO37,BO209) -> 0 | BP21: =SUM(BP37,BP209) -> 731 | BQ21: =SUM(AF21-AS21) -> 16304 | BR21: =SUM(BR37,BR209) -> 0 | BS21: =SUM(BS37,BS209) -> 0 | BT21: =SUM(BT37,BT209) -> 0 | BU21: =SUM(BU37,BU209) -> 0 | BV21: =SUM(BV37,BV209) -> 0 | BW21: =SUM(BW37,BW209) -> 0 | BX21: =SUM(BX37,BX209) -> 0 | BY21: =SUM(BY37,BY209) -> 0 | ... CO21: =SUM(CO37,CO209) -> 4888 | CP21: =SUM(CM21,CK21,CO21) -> 213819 | CQ21: =SUM(CQ37,CQ209) -> 27791 | CR21: =SUM(CR37,CR209) -> 0 | CS21: =SUM(CS37,CS209) -> 0 | CT21: =SUM(CT37,CT209) -> 0 | CU21: =SUM(CU37,CU209) -> 0 | CV21: =SUM(CV37,CV209) -> 0 | CW21: =SUM(CW37,CW209) -> 73200 | CX21: =SUM(CX37,CX209) -> 73200 | ... DA21: =SUM(DA37,DA209) -> 0 | DB21: =SUM(CP21,CQ21,DA21) -> 241610 | DC21: =SUM(CO21,CN21) -> 5102 | DD21: =SUM(DD37,DD209) -> 0 | DE21: =SUM(DE37,DE53) -> 0 | DF21: =SUM(DF37,DF53) -> 0 | DG21: =SUM(DB21,DF21) -> 241610 | DH21: =SUM(DC21) -> 5102 | DI21: =SUM(DI37,DI53) -> 0 | DJ21: =SUM(DJ37,DJ53) -> 0 | DK21: =SUM(DK37,DK53) -> 0 | DL21: =SUM(DL37,DL53) -> 0 | DM21: =SUM(DM37,DM53) -> 0 | DN21: =SUM(DN37,DN53) -> 0 | DO21: =SUM(DO37,DO53) -> 0 | DP21: =SUM(DP37,DP53) -> 0 | ... EH21: =SUM(EH37,EH53) -> 0
C22: Г.Мусрепова | Y22: =SUM(Y38,Y210) -> 303 | AF22: =SUM(AS22:AU22,AY22,BA22:BB22,BG22:BL22) -> 961408 | AG22: =SUM(AG38,AG210) -> 789735 | AH22: =SUM(AH38,AH210) -> 82 | AI22: =SUM(AI38,AI210) -> 63 | AJ22: =SUM(AJ38,AJ210) -> 19 | AK22: =SUM(AK38,AK210) -> 0 | AL22: =SUM(AL38,AL210) -> 0 | AM22: =SUM(AM38,AM210) -> 0 | AN22: =SUM(AN38,AN210) -> 0 | ... AR22: =SUM(AR38,AR210) -> 0 | AS22: =SUM(AG22,AH22,AK22,AL22,AO22) -> 947550 | AT22: =SUM(AT38,AT210) -> 0 | AU22: =SUM(AV22:AX22) -> 0 | AV22: =SUM(AV38,AV210) -> 0 | AW22: =SUM(AW38,AW210) -> 0 | AX22: =SUM(AX38,AX210) -> 0 | AY22: =SUM(AY38,AY210) -> 3466 | AZ22: =SUM(AZ38,AZ210) -> 73 | BA22: =SUM(BA38,BA210) -> 2024 | BB22: =SUM(BC22,BD22,BF22) -> 2159 | BC22: =SUM(BC38,BC210) -> 1384 | BD22: =SUM(BD38,BD210) -> 450 | BE22: =SUM(BE38,BE210) -> 0 | BF22: =SUM(BF38,BF210) -> 325 | BG22: =SUM(BG38,BG210) -> 0 | BH22: =SUM(BH38,BH210) -> 3901 | BI22: =SUM(BI38,BI210) -> 1 | BJ22: =SUM(BJ38,BJ210) -> 35 | BK22: =SUM(BK38,BK210) -> 238 | BL22: =SUM(BM22:BP22) -> 2034 | BM22: =SUM(BM38,BM210) -> 0 | BN22: =SUM(BN38,BN210) -> 0 | BO22: =SUM(BO38,BO210) -> 0 | BP22: =SUM(BP38,BP210) -> 2034 | BQ22: =SUM(AF22-AS22) -> 13858 | BR22: =SUM(BR38,BR210) -> 9257 | BS22: =SUM(BS38,BS210) -> 0 | BT22: =SUM(BT38,BT210) -> 6805 | BU22: =SUM(BU38,BU210) -> 0 | BV22: =SUM(BV38,BV210) -> 0 | BW22: =SUM(BW38,BW210) -> 0 | BX22: =SUM(BX38,BX210) -> 0 | BY22: =SUM(BY38,BY210) -> 0 | ... CO22: =SUM(CO38,CO210) -> 39047 | CP22: =SUM(CM22,CK22,CO22) -> 719517 | CQ22: =SUM(CQ38,CQ210) -> 64543 | CR22: =SUM(CR38,CR210) -> 0 | CS22: =SUM(CS38,CS210) -> 0 | CT22: =SUM(CT38,CT210) -> 0 | CU22: =SUM(CU38,CU210) -> 0 | CV22: =SUM(CV38,CV210) -> 0 | CW22: =SUM(CW38,CW210) -> 0 | CX22: =SUM(CX38,CX210) -> 0 | ... DA22: =SUM(DA38,DA210) -> 0 | DB22: =SUM(CP22,CQ22,DA22) -> 784060 | DC22: =SUM(CO22,CN22) -> 39047 | DD22: =SUM(DD38,DD210) -> 0 | DE22: =SUM(DE38,DE54) -> 0 | DF22: =SUM(DF38,DF54) -> 0 | DG22: =SUM(DB22,DF22) -> 784060 | DH22: =SUM(DC22) -> 39047 | DI22: =SUM(DI38,DI54) -> 0 | DJ22: =SUM(DJ38,DJ54) -> 0 | DK22: =SUM(DK38,DK54) -> 0 | DL22: =SUM(DL38,DL54) -> 0 | DM22: =SUM(DM38,DM54) -> 0 | DN22: =SUM(DN38,DN54) -> 0 | DO22: =SUM(DO38,DO54) -> 0 | DP22: =SUM(DP38,DP54) -> 0 | ... EH22: =SUM(EH38,EH54) -> 0
C23: Есильский | Y23: =SUM(Y39,Y211) -> 292 | AF23: =SUM(AS23:AU23,AY23,BA23:BB23,BG23:BL23) -> 401834 | AG23: =SUM(AG39,AG211) -> 319173 | AH23: =SUM(AH39,AH211) -> 114 | AI23: =SUM(AI39,AI211) -> 78 | AJ23: =SUM(AJ39,AJ211) -> 0 | AK23: =SUM(AK39,AK211) -> 0 | AL23: =SUM(AL39,AL211) -> 5494 | AM23: =SUM(AM39,AM211) -> 3420 | AN23: =SUM(AN39,AN211) -> 0 | ... AR23: =SUM(AR39,AR211) -> 0 | AS23: =SUM(AG23,AH23,AK23,AL23,AO23) -> 389372 | AT23: =SUM(AT39,AT211) -> 0 | AU23: =SUM(AV23:AX23) -> 0 | AV23: =SUM(AV39,AV211) -> 0 | AW23: =SUM(AW39,AW211) -> 0 | AX23: =SUM(AX39,AX211) -> 0 | AY23: =SUM(AY39,AY211) -> 3189 | AZ23: =SUM(AZ39,AZ211) -> 454 | BA23: =SUM(BA39,BA211) -> 3084 | BB23: =SUM(BC23,BD23,BF23) -> 3235 | BC23: =SUM(BC39,BC211) -> 430 | BD23: =SUM(BD39,BD211) -> 2747 | BE23: =SUM(BE39,BE211) -> 2741 | BF23: =SUM(BF39,BF211) -> 58 | BG23: =SUM(BG39,BG211) -> 65 | BH23: =SUM(BH39,BH211) -> 2213 | BI23: =SUM(BI39,BI211) -> 1 | BJ23: =SUM(BJ39,BJ211) -> 116 | BK23: =SUM(BK39,BK211) -> 19 | BL23: =SUM(BM23:BP23) -> 540 | BM23: =SUM(BM39,BM211) -> 10 | BN23: =SUM(BN39,BN211) -> 0 | BO23: =SUM(BO39,BO211) -> 0 | BP23: =SUM(BP39,BP211) -> 530 | BQ23: =SUM(AF23-AS23) -> 12462 | BR23: =SUM(BR39,BR211) -> 386 | BS23: =SUM(BS39,BS211) -> 0 | BT23: =SUM(BT39,BT211) -> 386 | BU23: =SUM(BU39,BU211) -> 0 | BV23: =SUM(BV39,BV211) -> 0 | BW23: =SUM(BW39,BW211) -> 0 | BX23: =SUM(BX39,BX211) -> 0 | BY23: =SUM(BY39,BY211) -> 0 | ... CO23: =SUM(CO39,CO211) -> 6874 | CP23: =SUM(CM23,CK23,CO23) -> 272324.31 | CQ23: =SUM(CQ39,CQ211) -> 44060.69 | CR23: =SUM(CR39,CR211) -> 0 | CS23: =SUM(CS39,CS211) -> 0 | CT23: =SUM(CT39,CT211) -> 0 | CU23: =SUM(CU39,CU211) -> 0 | CV23: =SUM(CV39,CV211) -> 0 | CW23: =SUM(CW39,CW211) -> 145000 | CX23: =SUM(CX39,CX211) -> 145000 | ... DA23: =SUM(DA39,DA211) -> 0 | DB23: =SUM(CP23,CQ23,DA23) -> 316385 | DC23: =SUM(CO23,CN23) -> 7420 | DD23: =SUM(DD39,DD211) -> 0 | DE23: =SUM(DE39,DE55) -> 0 | DF23: =SUM(DF39,DF55) -> 0 | DG23: =SUM(DB23,DF23) -> 316385 | DH23: =SUM(DC23) -> 7420 | DI23: =SUM(DI39,DI55) -> 0 | DJ23: =SUM(DJ39,DJ55) -> 0 | DK23: =SUM(DK39,DK55) -> 0 | DL23: =SUM(DL39,DL55) -> 0 | DM23: =SUM(DM39,DM55) -> 0 | DN23: =SUM(DN39,DN55) -> 0 | DO23: =SUM(DO39,DO55) -> 0 | DP23: =SUM(DP39,DP55) -> 0 | ... EH23: =SUM(EH39,EH55) -> 0
C24: Жамбылский | Y24: =SUM(Y40,Y212) -> 303 | AF24: =SUM(AS24:AU24,AY24,BA24:BB24,BG24:BL24) -> 527568 | AG24: =SUM(AG40,AG212) -> 348615 | AH24: =SUM(AH40,AH212) -> 67 | AI24: =SUM(AI40,AI212) -> 58 | AJ24: =SUM(AJ40,AJ212) -> 0 | AK24: =SUM(AK40,AK212) -> 0 | AL24: =SUM(AL40,AL212) -> 0 | AM24: =SUM(AM40,AM212) -> 0 | AN24: =SUM(AN40,AN212) -> 0 | ... AR24: =SUM(AR40,AR212) -> 0 | AS24: =SUM(AG24,AH24,AK24,AL24,AO24) -> 493583 | AT24: =SUM(AT40,AT212) -> 0 | AU24: =SUM(AV24:AX24) -> 0 | AV24: =SUM(AV40,AV212) -> 0 | AW24: =SUM(AW40,AW212) -> 0 | AX24: =SUM(AX40,AX212) -> 0 | AY24: =SUM(AY40,AY212) -> 4375 | AZ24: =SUM(AZ40,AZ212) -> 92 | BA24: =SUM(BA40,BA212) -> 7028 | BB24: =SUM(BC24,BD24,BF24) -> 18253 | BC24: =SUM(BC40,BC212) -> 1 | BD24: =SUM(BD40,BD212) -> 18226 | BE24: =SUM(BE40,BE212) -> 13355 | BF24: =SUM(BF40,BF212) -> 26 | BG24: =SUM(BG40,BG212) -> 0 | BH24: =SUM(BH40,BH212) -> 2731 | BI24: =SUM(BI40,BI212) -> 0 | BJ24: =SUM(BJ40,BJ212) -> 77 | BK24: =SUM(BK40,BK212) -> 0 | BL24: =SUM(BM24:BP24) -> 1521 | BM24: =SUM(BM40,BM212) -> 0 | BN24: =SUM(BN40,BN212) -> 0 | BO24: =SUM(BO40,BO212) -> 0 | BP24: =SUM(BP40,BP212) -> 1521 | BQ24: =SUM(AF24-AS24) -> 33985 | BR24: =SUM(BR40,BR212) -> 0 | BS24: =SUM(BS40,BS212) -> 0 | BT24: =SUM(BT40,BT212) -> 0 | BU24: =SUM(BU40,BU212) -> 0 | BV24: =SUM(BV40,BV212) -> 0 | BW24: =SUM(BW40,BW212) -> 0 | BX24: =SUM(BX40,BX212) -> 0 | BY24: =SUM(BY40,BY212) -> 0 | ... CO24: =SUM(CO40,CO212) -> 10743 | CP24: =SUM(CM24,CK24,CO24) -> 306148 | CQ24: =SUM(CQ40,CQ212) -> 39434 | CR24: =SUM(CR40,CR212) -> 0 | CS24: =SUM(CS40,CS212) -> 0 | CT24: =SUM(CT40,CT212) -> 0 | CU24: =SUM(CU40,CU212) -> 0 | CV24: =SUM(CV40,CV212) -> 0 | CW24: =SUM(CW40,CW212) -> 0 | CX24: =SUM(CX40,CX212) -> 0 | ... DA24: =SUM(DA40,DA212) -> 0 | DB24: =SUM(CP24,CQ24,DA24) -> 345582 | DC24: =SUM(CO24,CN24) -> 11345 | DD24: =SUM(DD40,DD212) -> 0 | DE24: =SUM(DE40,DE56) -> 0 | DF24: =SUM(DF40,DF56) -> 0 | DG24: =SUM(DB24,DF24) -> 345582 | DH24: =SUM(DC24) -> 11345 | DI24: =SUM(DI40,DI56) -> 0 | DJ24: =SUM(DJ40,DJ56) -> 0 | DK24: =SUM(DK40,DK56) -> 0 | DL24: =SUM(DL40,DL56) -> 0 | DM24: =SUM(DM40,DM56) -> 0 | DN24: =SUM(DN40,DN56) -> 0 | DO24: =SUM(DO40,DO56) -> 0 | DP24: =SUM(DP40,DP56) -> 0 | ... EH24: =SUM(EH40,EH56) -> 0
C25: Кызылжарский | Y25: =SUM(Y41,Y213) -> 424 | AF25: =SUM(AS25:AU25,AY25,BA25:BB25,BG25:BL25) -> 366966 | AG25: =SUM(AG41,AG213) -> 221261 | AH25: =SUM(AH41,AH213) -> 28 | AI25: =SUM(AI41,AI213) -> 2 | AJ25: =SUM(AJ41,AJ213) -> 26 | AK25: =SUM(AK41,AK213) -> 0 | AL25: =SUM(AL41,AL213) -> 8334 | AM25: =SUM(AM41,AM213) -> 686 | AN25: =SUM(AN41,AN213) -> 0 | ... AR25: =SUM(AR41,AR213) -> 0 | AS25: =SUM(AG25,AH25,AK25,AL25,AO25) -> 345985 | AT25: =SUM(AT41,AT213) -> 0 | AU25: =SUM(AV25:AX25) -> 175 | AV25: =SUM(AV41,AV213) -> 0 | AW25: =SUM(AW41,AW213) -> 0 | AX25: =SUM(AX41,AX213) -> 175 | AY25: =SUM(AY41,AY213) -> 3618 | AZ25: =SUM(AZ41,AZ213) -> 588 | BA25: =SUM(BA41,BA213) -> 6764 | BB25: =SUM(BC25,BD25,BF25) -> 7168 | BC25: =SUM(BC41,BC213) -> 677 | BD25: =SUM(BD41,BD213) -> 6428 | BE25: =SUM(BE41,BE213) -> 6261 | BF25: =SUM(BF41,BF213) -> 63 | BG25: =SUM(BG41,BG213) -> 53 | BH25: =SUM(BH41,BH213) -> 2509 | BI25: =SUM(BI41,BI213) -> 0 | BJ25: =SUM(BJ41,BJ213) -> 0 | BK25: =SUM(BK41,BK213) -> 0 | BL25: =SUM(BM25:BP25) -> 694 | BM25: =SUM(BM41,BM213) -> 0 | BN25: =SUM(BN41,BN213) -> 0 | BO25: =SUM(BO41,BO213) -> 0 | BP25: =SUM(BP41,BP213) -> 694 | BQ25: =SUM(AF25-AS25) -> 20981 | BR25: =SUM(BR41,BR213) -> 1022 | BS25: =SUM(BS41,BS213) -> 0 | BT25: =SUM(BT41,BT213) -> 827 | BU25: =SUM(BU41,BU213) -> 0 | BV25: =SUM(BV41,BV213) -> 0 | BW25: =SUM(BW41,BW213) -> 0 | BX25: =SUM(BX41,BX213) -> 0 | BY25: =SUM(BY41,BY213) -> 0 | ... CO25: =SUM(CO41,CO213) -> 3924 | CP25: =SUM(CM25,CK25,CO25) -> 201367.2 | CQ25: =SUM(CQ41,CQ213) -> 17255.8 | CR25: =SUM(CR41,CR213) -> 0 | CS25: =SUM(CS41,CS213) -> 0 | CT25: =SUM(CT41,CT213) -> 0 | CU25: =SUM(CU41,CU213) -> 0 | CV25: =SUM(CV41,CV213) -> 0 | CW25: =SUM(CW41,CW213) -> 0 | CX25: =SUM(CX41,CX213) -> 0 | ... DA25: =SUM(DA41,DA213) -> 0 | DB25: =SUM(CP25,CQ25,DA25) -> 218623 | DC25: =SUM(CO25,CN25) -> 3924 | DD25: =SUM(DD41,DD213) -> 0 | DE25: =SUM(DE41,DE57) -> 0 | DF25: =SUM(DF41,DF57) -> 0 | DG25: =SUM(DB25,DF25) -> 218623 | DH25: =SUM(DC25) -> 3924 | DI25: =SUM(DI41,DI57) -> 0 | DJ25: =SUM(DJ41,DJ57) -> 0 | DK25: =SUM(DK41,DK57) -> 0 | DL25: =SUM(DL41,DL57) -> 0 | DM25: =SUM(DM41,DM57) -> 0 | DN25: =SUM(DN41,DN57) -> 0 | DO25: =SUM(DO41,DO57) -> 0 | DP25: =SUM(DP41,DP57) -> 0 | ... EH25: =SUM(EH41,EH57) -> 0
C26: М.Жумабаева | Y26: =SUM(Y42,Y214) -> 317 | AF26: =SUM(AS26:AU26,AY26,BA26:BB26,BG26:BL26) -> 590633 | AG26: =SUM(AG42,AG214) -> 467390 | AH26: =SUM(AH42,AH214) -> 80 | AI26: =SUM(AI42,AI214) -> 19 | AJ26: =SUM(AJ42,AJ214) -> 0 | AK26: =SUM(AK42,AK214) -> 0 | AL26: =SUM(AL42,AL214) -> 0 | AM26: =SUM(AM42,AM214) -> 0 | AN26: =SUM(AN42,AN214) -> 0 | ... AR26: =SUM(AR42,AR214) -> 0 | AS26: =SUM(AG26,AH26,AK26,AL26,AO26) -> 568795 | AT26: =SUM(AT42,AT214) -> 0 | AU26: =SUM(AV26:AX26) -> 0 | AV26: =SUM(AV42,AV214) -> 0 | AW26: =SUM(AW42,AW214) -> 0 | AX26: =SUM(AX42,AX214) -> 0 | AY26: =SUM(AY42,AY214) -> 10275 | AZ26: =SUM(AZ42,AZ214) -> 1177 | BA26: =SUM(BA42,BA214) -> 2929 | BB26: =SUM(BC26,BD26,BF26) -> 3019 | BC26: =SUM(BC42,BC214) -> 0 | BD26: =SUM(BD42,BD214) -> 2864 | BE26: =SUM(BE42,BE214) -> 127 | BF26: =SUM(BF42,BF214) -> 155 | BG26: =SUM(BG42,BG214) -> 0 | BH26: =SUM(BH42,BH214) -> 3204 | BI26: =SUM(BI42,BI214) -> 1 | BJ26: =SUM(BJ42,BJ214) -> 21 | BK26: =SUM(BK42,BK214) -> 0 | BL26: =SUM(BM26:BP26) -> 2389 | BM26: =SUM(BM42,BM214) -> 0 | BN26: =SUM(BN42,BN214) -> 0 | BO26: =SUM(BO42,BO214) -> 0 | BP26: =SUM(BP42,BP214) -> 2389 | BQ26: =SUM(AF26-AS26) -> 21838 | BR26: =SUM(BR42,BR214) -> 0 | BS26: =SUM(BS42,BS214) -> 0 | BT26: =SUM(BT42,BT214) -> 0 | BU26: =SUM(BU42,BU214) -> 0 | BV26: =SUM(BV42,BV214) -> 0 | BW26: =SUM(BW42,BW214) -> 0 | BX26: =SUM(BX42,BX214) -> 0 | BY26: =SUM(BY42,BY214) -> 0 | ... CO26: =SUM(CO42,CO214) -> 22102 | CP26: =SUM(CM26,CK26,CO26) -> 416768 | CQ26: =SUM(CQ42,CQ214) -> 51023 | CR26: =SUM(CR42,CR214) -> 333 | CS26: =SUM(CS42,CS214) -> 0 | CT26: =SUM(CT42,CT214) -> 0 | CU26: =SUM(CU42,CU214) -> 0 | CV26: =SUM(CV42,CV214) -> 0 | CW26: =SUM(CW42,CW214) -> 300000 | CX26: =SUM(CX42,CX214) -> 300000 | ... DA26: =SUM(DA42,DA214) -> 0 | DB26: =SUM(CP26,CQ26,DA26) -> 467791 | DC26: =SUM(CO26,CN26) -> 22556 | DD26: =SUM(DD42,DD214) -> 0 | DE26: =SUM(DE42,DE58) -> 0 | DF26: =SUM(DF42,DF58) -> 0 | DG26: =SUM(DB26,DF26) -> 467791 | DH26: =SUM(DC26) -> 22556 | DI26: =SUM(DI42,DI58) -> 0 | DJ26: =SUM(DJ42,DJ58) -> 0 | DK26: =SUM(DK42,DK58) -> 0 | DL26: =SUM(DL42,DL58) -> 0 | DM26: =SUM(DM42,DM58) -> 0 | DN26: =SUM(DN42,DN58) -> 0 | DO26: =SUM(DO42,DO58) -> 0 | DP26: =SUM(DP42,DP58) -> 0 | ... EH26: =SUM(EH42,EH58) -> 0
C27: Мамлютский | Y27: =SUM(Y43,Y215) -> 243 | AF27: =SUM(AS27:AU27,AY27,BA27:BB27,BG27:BL27) -> 294792.8 | AG27: =SUM(AG43,AG215) -> 199147.7 | AH27: =SUM(AH43,AH215) -> 49 | AI27: =SUM(AI43,AI215) -> 2 | AJ27: =SUM(AJ43,AJ215) -> 0 | AK27: =SUM(AK43,AK215) -> 51 | AL27: =SUM(AL43,AL215) -> 107 | AM27: =SUM(AM43,AM215) -> 0 | AN27: =SUM(AN43,AN215) -> 0 | ... AR27: =SUM(AR43,AR215) -> 0 | AS27: =SUM(AG27,AH27,AK27,AL27,AO27) -> 275452.4 | AT27: =SUM(AT43,AT215) -> 0 | AU27: =SUM(AV27:AX27) -> 0 | AV27: =SUM(AV43,AV215) -> 0 | AW27: =SUM(AW43,AW215) -> 0 | AX27: =SUM(AX43,AX215) -> 0 | AY27: =SUM(AY43,AY215) -> 2024.4 | AZ27: =SUM(AZ43,AZ215) -> 322 | BA27: =SUM(BA43,BA215) -> 7084.6 | BB27: =SUM(BC27,BD27,BF27) -> 8270.1 | BC27: =SUM(BC43,BC215) -> 0 | BD27: =SUM(BD43,BD215) -> 8249.1 | BE27: =SUM(BE43,BE215) -> 7764 | BF27: =SUM(BF43,BF215) -> 21 | BG27: =SUM(BG43,BG215) -> 0 | BH27: =SUM(BH43,BH215) -> 1596.3 | BI27: =SUM(BI43,BI215) -> 0 | BJ27: =SUM(BJ43,BJ215) -> 8 | BK27: =SUM(BK43,BK215) -> 0 | BL27: =SUM(BM27:BP27) -> 357 | BM27: =SUM(BM43,BM215) -> 0 | BN27: =SUM(BN43,BN215) -> 0 | BO27: =SUM(BO43,BO215) -> 0 | BP27: =SUM(BP43,BP215) -> 357 | BQ27: =SUM(AF27-AS27) -> 19340.4 | BR27: =SUM(BR43,BR215) -> 62 | BS27: =SUM(BS43,BS215) -> 0 | BT27: =SUM(BT43,BT215) -> 40 | BU27: =SUM(BU43,BU215) -> 0 | BV27: =SUM(BV43,BV215) -> 5 | BW27: =SUM(BW43,BW215) -> 0 | BX27: =SUM(BX43,BX215) -> 0 | BY27: =SUM(BY43,BY215) -> 0 | ... CO27: =SUM(CO43,CO215) -> 6500 | CP27: =SUM(CM27,CK27,CO27) -> 170385 | CQ27: =SUM(CQ43,CQ215) -> 27197 | CR27: =SUM(CR43,CR215) -> 0 | CS27: =SUM(CS43,CS215) -> 0 | CT27: =SUM(CT43,CT215) -> 0 | CU27: =SUM(CU43,CU215) -> 0 | CV27: =SUM(CV43,CV215) -> 0 | CW27: =SUM(CW43,CW215) -> 99964 | CX27: =SUM(CX43,CX215) -> 99964 | ... DA27: =SUM(DA43,DA215) -> 0 | DB27: =SUM(CP27,CQ27,DA27) -> 197582 | DC27: =SUM(CO27,CN27) -> 7192 | DD27: =SUM(DD43,DD215) -> 0 | DE27: =SUM(DE43,DE59) -> 51 | DF27: =SUM(DF43,DF59) -> 51 | DG27: =SUM(DB27,DF27) -> 197633 | DH27: =SUM(DC27) -> 7192 | DI27: =SUM(DI43,DI59) -> 0 | DJ27: =SUM(DJ43,DJ59) -> 0 | DK27: =SUM(DK43,DK59) -> 0 | DL27: =SUM(DL43,DL59) -> 0 | DM27: =SUM(DM43,DM59) -> 0 | DN27: =SUM(DN43,DN59) -> 0 | DO27: =SUM(DO43,DO59) -> 0 | DP27: =SUM(DP43,DP59) -> 0 | ... EH27: =SUM(EH43,EH59) -> 0
C28: Тайыншинский | Y28: =SUM(Y44,Y216) -> 458 | AF28: =SUM(AS28:AU28,AY28,BA28:BB28,BG28:BL28) -> 928964 | AG28: =SUM(AG44,AG216) -> 714022 | AH28: =SUM(AH44,AH216) -> 95 | AI28: =SUM(AI44,AI216) -> 54 | AJ28: =SUM(AJ44,AJ216) -> 0 | AK28: =SUM(AK44,AK216) -> 0 | AL28: =SUM(AL44,AL216) -> 181 | AM28: =SUM(AM44,AM216) -> 131 | AN28: =SUM(AN44,AN216) -> 0 | ... AR28: =SUM(AR44,AR216) -> 0 | AS28: =SUM(AG28,AH28,AK28,AL28,AO28) -> 912564 | AT28: =SUM(AT44,AT216) -> 0 | AU28: =SUM(AV28:AX28) -> 7 | AV28: =SUM(AV44,AV216) -> 7 | AW28: =SUM(AW44,AW216) -> 0 | AX28: =SUM(AX44,AX216) -> 0 | AY28: =SUM(AY44,AY216) -> 3140 | AZ28: =SUM(AZ44,AZ216) -> 792 | BA28: =SUM(BA44,BA216) -> 2316 | BB28: =SUM(BC28,BD28,BF28) -> 4443 | BC28: =SUM(BC44,BC216) -> 150 | BD28: =SUM(BD44,BD216) -> 3873 | BE28: =SUM(BE44,BE216) -> 0 | BF28: =SUM(BF44,BF216) -> 420 | BG28: =SUM(BG44,BG216) -> 0 | BH28: =SUM(BH44,BH216) -> 3235 | BI28: =SUM(BI44,BI216) -> 0 | BJ28: =SUM(BJ44,BJ216) -> 76 | BK28: =SUM(BK44,BK216) -> 0 | BL28: =SUM(BM28:BP28) -> 3183 | BM28: =SUM(BM44,BM216) -> 0 | BN28: =SUM(BN44,BN216) -> 0 | BO28: =SUM(BO44,BO216) -> 0 | BP28: =SUM(BP44,BP216) -> 3183 | BQ28: =SUM(AF28-AS28) -> 16400 | BR28: =SUM(BR44,BR216) -> 2267 | BS28: =SUM(BS44,BS216) -> 0 | BT28: =SUM(BT44,BT216) -> 2164 | BU28: =SUM(BU44,BU216) -> 0 | BV28: =SUM(BV44,BV216) -> 0 | BW28: =SUM(BW44,BW216) -> 0 | BX28: =SUM(BX44,BX216) -> 0 | BY28: =SUM(BY44,BY216) -> 0 | ... CO28: =SUM(CO44,CO216) -> 44282 | CP28: =SUM(CM28,CK28,CO28) -> 639748 | CQ28: =SUM(CQ44,CQ216) -> 75509 | CR28: =SUM(CR44,CR216) -> 0 | CS28: =SUM(CS44,CS216) -> 0 | CT28: =SUM(CT44,CT216) -> 0 | CU28: =SUM(CU44,CU216) -> 0 | CV28: =SUM(CV44,CV216) -> 0 | CW28: =SUM(CW44,CW216) -> 0 | CX28: =SUM(CX44,CX216) -> 0 | ... DA28: =SUM(DA44,DA216) -> 0 | DB28: =SUM(CP28,CQ28,DA28) -> 715257 | DC28: =SUM(CO28,CN28) -> 47741 | DD28: =SUM(DD44,DD216) -> 0 | DE28: =SUM(DE44,DE60) -> 0 | DF28: =SUM(DF44,DF60) -> 0 | DG28: =SUM(DB28,DF28) -> 715257 | DH28: =SUM(DC28) -> 47741 | DI28: =SUM(DI44,DI60) -> 0 | DJ28: =SUM(DJ44,DJ60) -> 0 | DK28: =SUM(DK44,DK60) -> 0 | DL28: =SUM(DL44,DL60) -> 0 | DM28: =SUM(DM44,DM60) -> 0 | DN28: =SUM(DN44,DN60) -> 0 | DO28: =SUM(DO44,DO60) -> 0 | DP28: =SUM(DP44,DP60) -> 0 | ... EH28: =SUM(EH44,EH60) -> 0
C29: Тимирязевский | Y29: =SUM(Y45,Y217) -> 335 | AF29: =SUM(AS29:AU29,AY29,BA29:BB29,BG29:BL29) -> 366946 | AG29: =SUM(AG45,AG217) -> 300675 | AH29: =SUM(AH45,AH217) -> 7 | AI29: =SUM(AI45,AI217) -> 5 | AJ29: =SUM(AJ45,AJ217) -> 0 | AK29: =SUM(AK45,AK217) -> 0 | AL29: =SUM(AL45,AL217) -> 0 | AM29: =SUM(AM45,AM217) -> 0 | AN29: =SUM(AN45,AN217) -> 0 | ... AR29: =SUM(AR45,AR217) -> 0 | AS29: =SUM(AG29,AH29,AK29,AL29,AO29) -> 358120 | AT29: =SUM(AT45,AT217) -> 0 | AU29: =SUM(AV29:AX29) -> 0 | AV29: =SUM(AV45,AV217) -> 0 | AW29: =SUM(AW45,AW217) -> 0 | AX29: =SUM(AX45,AX217) -> 0 | AY29: =SUM(AY45,AY217) -> 4874 | AZ29: =SUM(AZ45,AZ217) -> 167 | BA29: =SUM(BA45,BA217) -> 977 | BB29: =SUM(BC29,BD29,BF29) -> 932 | BC29: =SUM(BC45,BC217) -> 6 | BD29: =SUM(BD45,BD217) -> 857 | BE29: =SUM(BE45,BE217) -> 751 | BF29: =SUM(BF45,BF217) -> 69 | BG29: =SUM(BG45,BG217) -> 0 | BH29: =SUM(BH45,BH217) -> 1449 | BI29: =SUM(BI45,BI217) -> 0 | BJ29: =SUM(BJ45,BJ217) -> 5 | BK29: =SUM(BK45,BK217) -> 0 | BL29: =SUM(BM29:BP29) -> 589 | BM29: =SUM(BM45,BM217) -> 0 | BN29: =SUM(BN45,BN217) -> 0 | BO29: =SUM(BO45,BO217) -> 0 | BP29: =SUM(BP45,BP217) -> 589 | BQ29: =SUM(AF29-AS29) -> 8826 | BR29: =SUM(BR45,BR217) -> 0 | BS29: =SUM(BS45,BS217) -> 0 | BT29: =SUM(BT45,BT217) -> 0 | BU29: =SUM(BU45,BU217) -> 0 | BV29: =SUM(BV45,BV217) -> 0 | BW29: =SUM(BW45,BW217) -> 0 | BX29: =SUM(BX45,BX217) -> 0 | BY29: =SUM(BY45,BY217) -> 0 | ... CO29: =SUM(CO45,CO217) -> 12227 | CP29: =SUM(CM29,CK29,CO29) -> 259398 | CQ29: =SUM(CQ45,CQ217) -> 35329 | CR29: =SUM(CR45,CR217) -> 0 | CS29: =SUM(CS45,CS217) -> 0 | CT29: =SUM(CT45,CT217) -> 0 | CU29: =SUM(CU45,CU217) -> 0 | CV29: =SUM(CV45,CV217) -> 0 | CW29: =SUM(CW45,CW217) -> 0 | CX29: =SUM(CX45,CX217) -> 0 | ... DA29: =SUM(DA45,DA217) -> 0 | DB29: =SUM(CP29,CQ29,DA29) -> 294727 | DC29: =SUM(CO29,CN29) -> 12730 | DD29: =SUM(DD45,DD217) -> 0 | DE29: =SUM(DE45,DE61) -> 0 | DF29: =SUM(DF45,DF61) -> 0 | DG29: =SUM(DB29,DF29) -> 294727 | DH29: =SUM(DC29) -> 12730 | DI29: =SUM(DI45,DI61) -> 0 | DJ29: =SUM(DJ45,DJ61) -> 0 | DK29: =SUM(DK45,DK61) -> 0 | DL29: =SUM(DL45,DL61) -> 0 | DM29: =SUM(DM45,DM61) -> 0 | DN29: =SUM(DN45,DN61) -> 0 | DO29: =SUM(DO45,DO61) -> 0 | DP29: =SUM(DP45,DP61) -> 0 | ... EH29: =SUM(EH45,EH61) -> 0
C30: Уалихановский | Y30: =SUM(Y46,Y218) -> 267 | AF30: =SUM(AS30:AU30,AY30,BA30:BB30,BG30:BL30) -> 954733 | AG30: =SUM(AG46,AG218) -> 339848 | AH30: =SUM(AH46,AH218) -> 32 | AI30: =SUM(AI46,AI218) -> 17 | AJ30: =SUM(AJ46,AJ218) -> 0 | AK30: =SUM(AK46,AK218) -> 40729 | AL30: =SUM(AL46,AL218) -> 328 | AM30: =SUM(AM46,AM218) -> 0 | AN30: =SUM(AN46,AN218) -> 0 | ... AR30: =SUM(AR46,AR218) -> 0 | AS30: =SUM(AG30,AH30,AK30,AL30,AO30) -> 911604 | AT30: =SUM(AT46,AT218) -> 0 | AU30: =SUM(AV30:AX30) -> 0 | AV30: =SUM(AV46,AV218) -> 0 | AW30: =SUM(AW46,AW218) -> 0 | AX30: =SUM(AX46,AX218) -> 0 | AY30: =SUM(AY46,AY218) -> 2139 | AZ30: =SUM(AZ46,AZ218) -> 395 | BA30: =SUM(BA46,BA218) -> 2257 | BB30: =SUM(BC30,BD30,BF30) -> 5909 | BC30: =SUM(BC46,BC218) -> 931 | BD30: =SUM(BD46,BD218) -> 4639 | BE30: =SUM(BE46,BE218) -> 0 | BF30: =SUM(BF46,BF218) -> 339 | BG30: =SUM(BG46,BG218) -> 0 | BH30: =SUM(BH46,BH218) -> 2867 | BI30: =SUM(BI46,BI218) -> 0 | BJ30: =SUM(BJ46,BJ218) -> 0 | BK30: =SUM(BK46,BK218) -> 0 | BL30: =SUM(BM30:BP30) -> 29957 | BM30: =SUM(BM46,BM218) -> 0 | BN30: =SUM(BN46,BN218) -> 0 | BO30: =SUM(BO46,BO218) -> 0 | BP30: =SUM(BP46,BP218) -> 29957 | BQ30: =SUM(AF30-AS30) -> 43129 | BR30: =SUM(BR46,BR218) -> 0 | BS30: =SUM(BS46,BS218) -> 0 | BT30: =SUM(BT46,BT218) -> 0 | BU30: =SUM(BU46,BU218) -> 0 | BV30: =SUM(BV46,BV218) -> 0 | BW30: =SUM(BW46,BW218) -> 0 | BX30: =SUM(BX46,BX218) -> 0 | BY30: =SUM(BY46,BY218) -> 0 | ... CO30: =SUM(CO46,CO218) -> 29591 | CP30: =SUM(CM30,CK30,CO30) -> 203182 | CQ30: =SUM(CQ46,CQ218) -> 34626 | CR30: =SUM(CR46,CR218) -> 0 | CS30: =SUM(CS46,CS218) -> 0 | CT30: =SUM(CT46,CT218) -> 0 | CU30: =SUM(CU46,CU218) -> 0 | CV30: =SUM(CV46,CV218) -> 0 | CW30: =SUM(CW46,CW218) -> 4053 | CX30: =SUM(CX46,CX218) -> 0 | ... DA30: =SUM(DA46,DA218) -> 81046 | DB30: =SUM(CP30,CQ30,DA30) -> 318854 | DC30: =SUM(CO30,CN30) -> 29591 | DD30: =SUM(DD46,DD218) -> 0 | DE30: =SUM(DE46,DE62) -> 0 | DF30: =SUM(DF46,DF62) -> 0 | DG30: =SUM(DB30,DF30) -> 318854 | DH30: =SUM(DC30) -> 29591 | DI30: =SUM(DI46,DI62) -> 0 | DJ30: =SUM(DJ46,DJ62) -> 0 | DK30: =SUM(DK46,DK62) -> 0 | DL30: =SUM(DL46,DL62) -> 0 | DM30: =SUM(DM46,DM62) -> 0 | DN30: =SUM(DN46,DN62) -> 0 | DO30: =SUM(DO46,DO62) -> 0 | DP30: =SUM(DP46,DP62) -> 0 | ... EH30: =SUM(EH46,EH62) -> 0
C31: Шал акына | Y31: =SUM(Y47,Y219) -> 246 | AF31: =SUM(AS31:AU31,AY31,BA31:BB31,BG31:BL31) -> 346149 | AG31: =SUM(AG47,AG219) -> 266344 | AH31: =SUM(AH47,AH219) -> 62 | AI31: =SUM(AI47,AI219) -> 19 | AJ31: =SUM(AJ47,AJ219) -> 0 | AK31: =SUM(AK47,AK219) -> 0 | AL31: =SUM(AL47,AL219) -> 897 | AM31: =SUM(AM47,AM219) -> 696 | AN31: =SUM(AN47,AN219) -> 0 | ... AR31: =SUM(AR47,AR219) -> 0 | AS31: =SUM(AG31,AH31,AK31,AL31,AO31) -> 340000 | AT31: =SUM(AT47,AT219) -> 0 | AU31: =SUM(AV31:AX31) -> 0 | AV31: =SUM(AV47,AV219) -> 0 | AW31: =SUM(AW47,AW219) -> 0 | AX31: =SUM(AX47,AX219) -> 0 | AY31: =SUM(AY47,AY219) -> 1812 | AZ31: =SUM(AZ47,AZ219) -> 194 | BA31: =SUM(BA47,BA219) -> 1248 | BB31: =SUM(BC31,BD31,BF31) -> 981 | BC31: =SUM(BC47,BC219) -> 339 | BD31: =SUM(BD47,BD219) -> 610 | BE31: =SUM(BE47,BE219) -> 8 | BF31: =SUM(BF47,BF219) -> 32 | BG31: =SUM(BG47,BG219) -> 0 | BH31: =SUM(BH47,BH219) -> 1687 | BI31: =SUM(BI47,BI219) -> 0 | BJ31: =SUM(BJ47,BJ219) -> 17 | BK31: =SUM(BK47,BK219) -> 0 | BL31: =SUM(BM31:BP31) -> 404 | BM31: =SUM(BM47,BM219) -> 0 | BN31: =SUM(BN47,BN219) -> 0 | BO31: =SUM(BO47,BO219) -> 0 | BP31: =SUM(BP47,BP219) -> 404 | BQ31: =SUM(AF31-AS31) -> 6149 | BR31: =SUM(BR47,BR219) -> 7176 | BS31: =SUM(BS47,BS219) -> 0 | BT31: =SUM(BT47,BT219) -> 6637 | BU31: =SUM(BU47,BU219) -> 0 | BV31: =SUM(BV47,BV219) -> 0 | BW31: =SUM(BW47,BW219) -> 0 | BX31: =SUM(BX47,BX219) -> 0 | BY31: =SUM(BY47,BY219) -> 0 | ... CO31: =SUM(CO47,CO219) -> 496 | CP31: =SUM(CM31,CK31,CO31) -> 229013 | CQ31: =SUM(CQ47,CQ219) -> 38977 | CR31: =SUM(CR47,CR219) -> 0 | CS31: =SUM(CS47,CS219) -> 0 | CT31: =SUM(CT47,CT219) -> 0 | CU31: =SUM(CU47,CU219) -> 0 | CV31: =SUM(CV47,CV219) -> 0 | CW31: =SUM(CW47,CW219) -> 98000 | CX31: =SUM(CX47,CX219) -> 0 | ... DA31: =SUM(DA47,DA219) -> 0 | DB31: =SUM(CP31,CQ31) -> 267990 | DC31: =SUM(CO31,CN31) -> 496 | DD31: =SUM(DD47,DD219) -> 0 | DE31: =SUM(DE47,DE63) -> 0 | DF31: =SUM(DF47,DF63) -> 0 | DG31: =SUM(DB31,DF31) -> 267990 | DH31: =SUM(DC31) -> 496 | DI31: =SUM(DI47,DI63) -> 0 | DJ31: =SUM(DJ47,DJ63) -> 0 | DK31: =SUM(DK47,DK63) -> 0 | DL31: =SUM(DL47,DL63) -> 0 | DM31: =SUM(DM47,DM63) -> 0 | DN31: =SUM(DN47,DN63) -> 0 | DO31: =SUM(DO47,DO63) -> 0 | DP31: =SUM(DP47,DP63) -> 0 | ... EH31: =SUM(EH47,EH63) -> 0
C32: г.Петропавловск | Y32: =SUM(Y48,Y220) -> 0 | AF32: =SUM(AS32:AU32,AY32,BA32:BB32,BG32:BL32) -> 0 | AG32: =SUM(AG48,AG220) -> 0 | AH32: =SUM(AH48,AH220) -> 0 | AI32: =SUM(AI48,AI220) -> 0 | AJ32: =SUM(AJ48,AJ220) -> 0 | AK32: =SUM(AK48,AK220) -> 0 | AL32: =SUM(AL48,AL220) -> 0 | AM32: =SUM(AM48,AM220) -> 0 | AN32: =SUM(AN48,AN220) -> 0 | ... AR32: =SUM(AR48,AR220) -> 0 | AS32: =SUM(AG32,AH32,AK32,AL32,AO32) -> 0 | AT32: =SUM(AT48,AT220) -> 0 | AU32: =SUM(AV32:AX32) -> 0 | AV32: =SUM(AV48,AV220) -> 0 | AW32: =SUM(AW48,AW220) -> 0 | AX32: =SUM(AX48,AX220) -> 0 | AY32: =SUM(AY48,AY220) -> 0 | AZ32: =SUM(AZ48,AZ220) -> 0 | BA32: =SUM(BA48,BA220) -> 0 | BB32: =SUM(BC32,BD32,BF32) -> 0 | BC32: =SUM(BC48,BC220) -> 0 | BD32: =SUM(BD48,BD220) -> 0 | BE32: =SUM(BE48,BE220) -> 0 | BF32: =SUM(BF48,BF220) -> 0 | BG32: =SUM(BG48,BG220) -> 0 | BH32: =SUM(BH48,BH220) -> 0 | BI32: =SUM(BI48,BI220) -> 0 | BJ32: =SUM(BJ48,BJ220) -> 0 | BK32: =SUM(BK48,BK220) -> 0 | BL32: =SUM(BM32:BP32) -> 0 | BM32: =SUM(BM48,BM220) -> 0 | BN32: =SUM(BN48,BN220) -> 0 | BO32: =SUM(BO48,BO220) -> 0 | BP32: =SUM(BP48,BP220) -> 0 | BQ32: =SUM(AF32-AS32) -> 0 | BR32: =SUM(BR48,BR220) -> 0 | BS32: =SUM(BS48,BS220) -> 0 | BT32: =SUM(BT48,BT220) -> 0 | BU32: =SUM(BU48,BU220) -> 0 | BV32: =SUM(BV48,BV220) -> 0 | BW32: =SUM(BW48,BW220) -> 0 | BX32: =SUM(BX48,BX220) -> 0 | BY32: =SUM(BY48,BY220) -> 0 | ... CH32: =SUM(CH48,CH220) -> 0 | CI32: =SUM(CI48,CI64) -> 0 | CJ32: =SUM(CJ48,CJ64) -> 0 | CK32: =SUM(CK48,CK220) -> 0 | CL32: =SUM(CL48,CL220) -> 0 | CM32: =SUM(CM48,CM220) -> 0 | CN32: =SUM(CN48,CN220) -> 0 | CO32: =SUM(CO48,CO220) -> 0 | CP32: =SUM(CM32,CK32,CO32) -> 0 | CQ32: =SUM(CQ48,CQ220) -> 0 | CR32: =SUM(CR48,CR220) -> 0 | CS32: =SUM(CS48,CS220) -> 0 | CT32: =SUM(CT48,CT220) -> 0 | CU32: =SUM(CU48,CU220) -> 0 | CV32: =SUM(CV48,CV220) -> 0 | CW32: =SUM(CW48,CW220) -> 0 | CX32: =SUM(CX48,CX220) -> 0 | ... DA32: =SUM(DA48,DA220) -> 0 | DB32: =SUM(CP32,CQ32) -> 0 | DC32: =SUM(CO32,CN32) -> 0 | DD32: =SUM(DD48,DD220) -> 0 | DE32: =SUM(DE48,DE64) -> 0 | DF32: =SUM(DF48,DF64) -> 0 | DG32: =SUM(DB32,DF32) -> 0 | DH32: =SUM(DC32) -> 0 | DI32: =SUM(DI48,DI64) -> 0 | DJ32: =SUM(DJ48,DJ64) -> 0 | DK32: =SUM(DK48,DK64) -> 0 | DL32: =SUM(DL48,DL64) -> 0 | DM32: =SUM(DM48,DM64) -> 0 | DN32: =SUM(DN48,DN64) -> 0 | DO32: =SUM(DO48,DO64) -> 0 | DP32: =SUM(DP48,DP64) -> 0 | ... EH32: =SUM(EH48,EH64) -> 0
B33: 1.1 | C33: Азаматтардың жері: Земли граждан: | Y33: =SUM(Y49,Y65,Y80,Y96,Y112,Y127,Y142,Y159) -> 3081 | AF33: =SUM(AS33:AU33,AY33,BA33:BB33,BG33:BL33) -> 1662.5 | AG33: =SUM(AG49,AG65,AG80,AG96,AG112,AG127,AG142,AG159) -> 993.6 | AH33: =SUM(AH49,AH65,AH80,AH96,AH112,AH127,AH142,AH159) -> 0.2 | AI33: =SUM(AI49,AI65,AI80,AI96,AI112,AI127,AI142,AI159) -> 0.1 | AJ33: =SUM(AJ49,AJ65,AJ80,AJ96,AJ112,AJ127,AJ142,AJ159) -> 0 | AK33: =SUM(AK49,AK65,AK80,AK96,AK112,AK127,AK142,AK159) -> 0.1 | AL33: =SUM(AL49,AL65,AL80,AL96,AL112,AL127,AL142,AL159) -> 4.5 | AM33: =SUM(AM49,AM65,AM80,AM96,AM112,AM127,AM142,AM159) -> 1.2 | AN33: =SUM(AN49,AN65,AN80,AN96,AN112,AN127,AN142,AN159) -> 0 | ... AQ33: =SUM(AQ49,AQ65,AQ80,AQ96,AQ112,AQ127,AQ142,AQ159) -> 179.9 | AR33: =SUM(AR49,AR65,AR112,AR159) -> 0 | AS33: =SUM(AG33,AH33,AK33,AL33,AO33) -> 1606.5 | AT33: =SUM(AT49,AT65,AT112,AT159) -> 0 | AU33: =SUM(AU49,AU65,AU112,AU159) -> 0 | AV33: =SUM(AV49,AV65,AV112,AV159) -> 0 | AW33: =SUM(AW49,AW65,AW112,AW159) -> 0 | AX33: =SUM(AX49,AX65,AX112,AX159) -> 0 | AY33: =SUM(AY49,AY65,AY112,AY159) -> 9.7 | AZ33: =SUM(AZ49,AZ65,AZ112,AZ159) -> 1.7 | BA33: =SUM(BA49,BA65,BA112,BA159) -> 9.4 | BB33: =SUM(BC33,BD33,BF33) -> 14 | BC33: =SUM(BC49,BC65,BC112,BC159) -> 1.1 | BD33: =SUM(BD49,BD65,BD112,BD159) -> 12.2 | BE33: =SUM(BE49,BE65,BE112,BE159) -> 6.6 | BF33: =SUM(BF49,BF65,BF112,BF159) -> 0.7 | BG33: =SUM(BG49,BG65,BG112,BG159) -> 0 | BH33: =SUM(BH49,BH65,BH112,BH159) -> 6.5 | BI33: =SUM(BI49,BI65,BI112,BI159) -> 0 | BJ33: =SUM(BJ49,BJ65,BJ112,BJ159) -> 0.3 | BK33: =SUM(BK49,BK65,BK112,BK159) -> 0.1 | BL33: =SUM(BM33:BP33) -> 16 | BM33: =SUM(BM49,BM65,BM112,BM159) -> 0 | BN33: =SUM(BN49,BN65,BN112,BN159) -> 0 | BO33: =SUM(BO49,BO65,BO112,BO159) -> 0 | BP33: =SUM(BP49,BP65,BP112,BP159) -> 16 | BQ33: =SUM(AU33,AY33,BA33,BB33,BG33,BH33,BI33,BJ33,BK33,BL33) -> 56 | BR33: =SUM(BR49,BR65,BR112,BR159) -> 3 | BS33: =SUM(BS49,BS65,BS112,BS159) -> 0 | BT33: =SUM(BT49,BT65,BT112,BT159) -> 1.6 | BU33: =SUM(BU49,BU65,BU112,BU159) -> 0 | BV33: =SUM(BV49,BV65,BV112,BV159) -> 0 | BW33: =SUM(BW49,BW65,BW112,BW159) -> 0 | BX33: =SUM(BX49,BX65,BX112,BX159) -> 0 | BY33: =SUM(BY49,BY65,BY112,BY159) -> 0 | ... CH33: =SUM(CH49,CH65,CH112,CH159) -> 3 | CK33: =SUM(CK49,CK65,CK112,CK159,CK96) -> 0.4 | CL33: =SUM(CL49,CL65,CL112,CL159,CL96) -> 0 | CM33: =SUM(CM49,CM65,CM112,CM159,CM96) -> 946.8 | CN33: =SUM(CN49,CN65,CN112,CN159,CN96) -> 1 | CO33: =SUM(CO49,CO65,CO112,CO159,CO96) -> 47.2 | CP33: =SUM(CM33,CK33,CO33) -> 994.4 | CQ33: =SUM(CQ49,CQ65,CQ112,CQ159,CQ96) -> 55.3 | CR33: =SUM(CR49,CR65,CR112,CR159,CR96) -> 0.3 | CS33: =SUM(CS49,CS65,CS112,CS159,CS96) -> 0 | CT33: =SUM(CT49,CT65,CT112,CT159,CT96) -> 0 | CU33: =SUM(CU49,CU65,CU112,CU159,CU96) -> 0 | CV33: =SUM(CV49,CV65,CV112,CV159,CV96) -> 0 | CW33: =SUM(CW49,CW65,CW112,CW159,CW96) -> 150.3 | CX33: =SUM(CX49,CX65,CX112,CX159,CX96) -> 119.3 | ... DA33: =SUM(DA49,DA65,DA112,DA159,DA96) -> 0 | DB33: =SUM(CP33,CQ33) -> 1049.7 | DC33: =SUM(CO33,CN33) -> 48.2 | DD33: =SUM(DD49,DD65,DD112,DD159,DD96) -> 0 | DE33: =SUM(DE49,DE65,DE112,DE159,DE96) -> 0.1 | DF33: =SUM(DF49,DF65,DF112,DF159,DF96) -> 0.1 | DG33: =SUM(DB33,DF33) -> 1049.8 | DH33: =SUM(DC33) -> 48.2
